Workbook
Name Slicer_Category: #N/A
Name Slicer_City: #N/A
Name Slicer_Customer_Name: #N/A
Name Slicer_Customer_Type: #N/A
Name Slicer_Top_5_Product: #N/A

Sheet Order
A1: Order_ID | B1: Order_Date | C1: Customer_ID | D1: Product_ID | E1: Emp_ID | F1: City | G1: Payment | H1: Qty | I1: Discount_% | J1: Delivery_Days | K1: Status | L1: Product Name | M1: Catgeroy | N1: Brand | O1: Unit_cost | P1: Seling_price | Q1: Gross Sales | R1: Discount Amount | S1: Net sales | T1: Total cost | U1: Profit
A2: ORD1001 | B2: 46113 | C2: C101 | D2: P201 | E2: E01 | F2: Delhi | G2: UPI | H2: 2 | I2: 0.05 | J2: 3 | K2: Delivered | L2: =_xlfn.XLOOKUP(D2,Products!A:A,Products!B:B) -> Laptop | M2: =_xlfn.XLOOKUP(D2,Products!A:A,Products!C:C) -> Electronics | N2: =_xlfn.XLOOKUP(D2,Products!A:A,Products!D:D) -> HP | O2: =_xlfn.XLOOKUP(D2,Products!A:A,Products!E:E) -> 42000 | P2: =_xlfn.XLOOKUP(D2,Products!A:A,Products!F:F) -> 55000 | Q2: =H2*P2 -> 110000 | R2: =Q2*I2 -> 5500 | S2: =Q2-R2 -> 104500 | T2: =H2*O2 -> 84000 | U2: =S2-T2 -> 20500
A3: ORD1002 | B3: 46113 | C3: C102 | D3: P205 | E3: E03 | F3: Noida | G3: Card | H3: 4 | I3: 0.1 | J3: 6 | K3: Delivered | L3: =_xlfn.XLOOKUP(D3,Products!A:A,Products!B:B) -> Jeans | M3: =_xlfn.XLOOKUP(D3,Products!A:A,Products!C:C) -> Clothing | N3: =_xlfn.XLOOKUP(D3,Products!A:A,Products!D:D) -> Wrangler | O3: =_xlfn.XLOOKUP(D3,Products!A:A,Products!E:E) -> 1100 | P3: =_xlfn.XLOOKUP(D3,Products!A:A,Products!F:F) -> 2200 | Q3: =H3*P3 -> 8800 | R3: =Q3*I3 -> 880 | S3: =Q3-R3 -> 7920 | T3: =H3*O3 -> 4400 | U3: =S3-T3 -> 3520
A4: ORD1003 | B4: 46114 | C4: C103 | D4: P210 | E4: E02 | F4: Jaipur | G4: COD | H4: 1 | I4: 0.07 | J4: 8 | K4: Returned | L4: =_xlfn.XLOOKUP(D4,Products!A:A,Products!B:B) -> Face Wash | M4: =_xlfn.XLOOKUP(D4,Products!A:A,Products!C:C) -> Beauty | N4: =_xlfn.XLOOKUP(D4,Products!A:A,Products!D:D) -> Nivea | O4: =_xlfn.XLOOKUP(D4,Products!A:A,Products!E:E) -> 180 | P4: =_xlfn.XLOOKUP(D4,Products!A:A,Products!F:F) -> 350 | Q4: =H4*P4 -> 350 | R4: =Q4*I4 -> 24.5 | S4: =Q4-R4 -> 325.5 | T4: =H4*O4 -> 180 | U4: =S4-T4 -> 145.5
A5: ORD1004 | B5: 46114 | C5: C104 | D5: P203 | E5: E04 | F5: Ghaziabad | G5: UPI | H5: 3 | I5: 0.05 | J5: 2 | K5: Delivered | L5: =_xlfn.XLOOKUP(D5,Products!A:A,Products!B:B) -> Headphones | M5: =_xlfn.XLOOKUP(D5,Products!A:A,Products!C:C) -> Electronics | N5: =_xlfn.XLOOKUP(D5,Products!A:A,Products!D:D) -> Sony | O5: =_xlfn.XLOOKUP(D5,Products!A:A,Products!E:E) -> 1800 | P5: =_xlfn.XLOOKUP(D5,Products!A:A,Products!F:F) -> 3200 | Q5: =H5*P5 -> 9600 | R5: =Q5*I5 -> 480 | S5: =Q5-R5 -> 9120 | T5: =H5*O5 -> 5400 | U5: =S5-T5 -> 3720
A6: ORD1005 | B6: 46115 | C6: C105 | D6: P207 | E6: E01 | F6: Meerut | G6: Cash | H6: 5 | I6: 0.12 | J6: 5 | K6: Delivered | L6: =_xlfn.XLOOKUP(D6,Products!A:A,Products!B:B) -> Office Chair | M6: =_xlfn.XLOOKUP(D6,Products!A:A,Products!C:C) -> Furniture | N6: =_xlfn.XLOOKUP(D6,Products!A:A,Products!D:D) -> Featherlite | O6: =_xlfn.XLOOKUP(D6,Products!A:A,Products!E:E) -> 4500 | P6: =_xlfn.XLOOKUP(D6,Products!A:A,Products!F:F) -> 7500 | Q6: =H6*P6 -> 37500 | R6: =Q6*I6 -> 4500 | S6: =Q6-R6 -> 33000 | T6: =H6*O6 -> 22500 | U6: =S6-T6 -> 10500
A7: ORD1006 | B7: 46115 | C7: C106 | D7: P202 | E7: E05 | F7: Delhi | G7: Card | H7: 1 | I7: 0.03 | J7: 4 | K7: Delivered | L7: =_xlfn.XLOOKUP(D7,Products!A:A,Products!B:B) -> Smartphone | M7: =_xlfn.XLOOKUP(D7,Products!A:A,Products!C:C) -> Electronics | N7: =_xlfn.XLOOKUP(D7,Products!A:A,Products!D:D) -> Samsung | O7: =_xlfn.XLOOKUP(D7,Products!A:A,Products!E:E) -> 14000 | P7: =_xlfn.XLOOKUP(D7,Products!A:A,Products!F:F) -> 22000 | Q7: =H7*P7 -> 22000 | R7: =Q7*I7 -> 660 | S7: =Q7-R7 -> 21340 | T7: =H7*O7 -> 14000 | U7: =S7-T7 -> 7340
A8: ORD1007 | B8: 46116 | C8: C107 | D8: P209 | E8: E02 | F8: Noida | G8: UPI | H8: 2 | I8: 0.08 | J8: 7 | K8: Cancelled | L8: =_xlfn.XLOOKUP(D8,Products!A:A,Products!B:B) -> Mixer Grinder | M8: =_xlfn.XLOOKUP(D8,Products!A:A,Products!C:C) -> Home Appliances | N8: =_xlfn.XLOOKUP(D8,Products!A:A,Products!D:D) -> Philips | O8: =_xlfn.XLOOKUP(D8,Products!A:A,Products!E:E) -> 2800 | P8: =_xlfn.XLOOKUP(D8,Products!A:A,Products!F:F) -> 4800 | Q8: =H8*P8 -> 9600 | R8: =Q8*I8 -> 768 | S8: =Q8-R8 -> 8832 | T8: =H8*O8 -> 5600 | U8: =S8-T8 -> 3232
A9: ORD1008 | B9: 46116 | C9: C108 | D9: P204 | E9: E03 | F9: Gurugram | G9: UPI | H9: 3 | I9: 0.06 | J9: 3 | K9: Delivered | L9: =_xlfn.XLOOKUP(D9,Products!A:A,Products!B:B) -> Shirt | M9: =_xlfn.XLOOKUP(D9,Products!A:A,Products!C:C) -> Clothing | N9: =_xlfn.XLOOKUP(D9,Products!A:A,Products!D:D) -> Levis | O9: =_xlfn.XLOOKUP(D9,Products!A:A,Products!E:E) -> 700 | P9: =_xlfn.XLOOKUP(D9,Products!A:A,Products!F:F) -> 1500 | Q9: =H9*P9 -> 4500 | R9: =Q9*I9 -> 270 | S9: =Q9-R9 -> 4230 | T9: =H9*O9 -> 2100 | U9: =S9-T9 -> 2130
A10: ORD1009 | B10: 46117 | C10: C109 | D10: P206 | E10: E04 | F10: Delhi | G10: COD | H10: 2 | I10: 0.1 | J10: 9 | K10: Returned | L10: =_xlfn.XLOOKUP(D10,Products!A:A,Products!B:B) -> Sports Shoes | M10: =_xlfn.XLOOKUP(D10,Products!A:A,Products!C:C) -> Sports | N10: =_xlfn.XLOOKUP(D10,Products!A:A,Products!D:D) -> Nike | O10: =_xlfn.XLOOKUP(D10,Products!A:A,Products!E:E) -> 2200 | P10: =_xlfn.XLOOKUP(D10,Products!A:A,Products!F:F) -> 4500 | Q10: =H10*P10 -> 9000 | R10: =Q10*I10 -> 900 | S10: =Q10-R10 -> 8100 | T10: =H10*O10 -> 4400 | U10: =S10-T10 -> 3700
A11: ORD1010 | B11: 46117 | C11: C110 | D11: P208 | E11: E05 | F11: Meerut | G11: Card | H11: 4 | I11: 0.05 | J11: 4 | K11: Delivered | L11: =_xlfn.XLOOKUP(D11,Products!A:A,Products!B:B) -> Study Table | M11: =_xlfn.XLOOKUP(D11,Products!A:A,Products!C:C) -> Furniture | N11: =_xlfn.XLOOKUP(D11,Products!A:A,Products!D:D) -> Ikea | O11: =_xlfn.XLOOKUP(D11,Products!A:A,Products!E:E) -> 5000 | P11: =_xlfn.XLOOKUP(D11,Products!A:A,Products!F:F) -> 8500 | Q11: =H11*P11 -> 34000 | R11: =Q11*I11 -> 1700 | S11: =Q11-R11 -> 32300 | T11: =H11*O11 -> 20000 | U11: =S11-T11 -> 12300
A12: ORD1011 | B12: 46118 | C12: C111 | D12: P201 | E12: E01 | F12: Noida | G12: UPI | H12: 1 | I12: 0.04 | J12: 2 | K12: Delivered | L12: =_xlfn.XLOOKUP(D12,Products!A:A,Products!B:B) -> Laptop | M12: =_xlfn.XLOOKUP(D12,Products!A:A,Products!C:C) -> Electronics | N12: =_xlfn.XLOOKUP(D12,Products!A:A,Products!D:D) -> HP | O12: =_xlfn.XLOOKUP(D12,Products!A:A,Products!E:E) -> 42000 | P12: =_xlfn.XLOOKUP(D12,Products!A:A,Products!F:F) -> 55000 | Q12: =H12*P12 -> 55000 | R12: =Q12*I12 -> 2200 | S12: =Q12-R12 -> 52800 | T12: =H12*O12 -> 42000 | U12: =S12-T12 -> 10800
A13: ORD1012 | B13: 46118 | C13: C112 | D13: P210 | E13: E02 | F13: Delhi | G13: Cash | H13: 2 | I13: 0.09 | J13: 6 | K13: Delivered | L13: =_xlfn.XLOOKUP(D13,Products!A:A,Products!B:B) -> Face Wash | M13: =_xlfn.XLOOKUP(D13,Products!A:A,Products!C:C) -> Beauty | N13: =_xlfn.XLOOKUP(D13,Products!A:A,Products!D:D) -> Nivea | O13: =_xlfn.XLOOKUP(D13,Products!A:A,Products!E:E) -> 180 | P13: =_xlfn.XLOOKUP(D13,Products!A:A,Products!F:F) -> 350 | Q13: =H13*P13 -> 700 | R13: =Q13*I13 -> 63 | S13: =Q13-R13 -> 637 | T13: =H13*O13 -> 360 | U13: =S13-T13 -> 277
... A501: ORD1500 | B501: 46113 | C501: C102 | D501: P205 | E501: E03 | F501: Noida | G501: Card | H501: 4.2860984 | I501: 0.14537815 | J501: 1.0590636 | K501: Delivered | L501: =_xlfn.XLOOKUP(D501,Products!A:A,Products!B:B) -> Jeans | M501: =_xlfn.XLOOKUP(D501,Products!A:A,Products!C:C) -> Clothing | N501: =_xlfn.XLOOKUP(D501,Products!A:A,Products!D:D) -> Wrangler | O501: =_xlfn.XLOOKUP(D501,Products!A:A,Products!E:E) -> 1100 | P501: =_xlfn.XLOOKUP(D501,Products!A:A,Products!F:F) -> 2200 | Q501: =H501*P501 -> 9429.4166 | R501: =Q501*I501 -> 1370.8311 | S501: =Q501-R501 -> 8058.5854 | T501: =H501*O501 -> 4714.7083 | U501: =S501-T501 -> 3343.8771

Sheet Products
A1: Product_ID | B1: Product_Name | C1: Category | D1: Brand | E1: Unit_Cost | F1: Selling_Price
A2: P201 | B2: Laptop | C2: Electronics | D2: HP | E2: 42000 | F2: 55000
A3: P202 | B3: Smartphone | C3: Electronics | D3: Samsung | E3: 14000 | F3: 22000
A4: P203 | B4: Headphones | C4: Electronics | D4: Sony | E4: 1800 | F4: 3200
A5: P204 | B5: Shirt | C5: Clothing | D5: Levis | E5: 700 | F5: 1500
A6: P205 | B6: Jeans | C6: Clothing | D6: Wrangler | E6: 1100 | F6: 2200
A7: P206 | B7: Sports Shoes | C7: Sports | D7: Nike | E7: 2200 | F7: 4500
A8: P207 | B8: Office Chair | C8: Furniture | D8: Featherlite | E8: 4500 | F8: 7500
A9: P208 | B9: Study Table | C9: Furniture | D9: Ikea | E9: 5000 | F9: 8500
A10: P209 | B10: Mixer Grinder | C10: Home Appliances | D10: Philips | E10: 2800 | F10: 4800
A11: P210 | B11: Face Wash | C11: Beauty | D11: Nivea | E11: 180 | F11: 350
A12: P211 | B12: Laptop | C12: Electronics | D12: HP | E12: 6781.3333 | F12: 7893.3333
A13: P212 | B13: Smartphone | C13: Electronics | D13: Samsung | E13: 9364.8485 | F13: 11320.303
... A501: P700 | B501: Face Wash | C501: Beauty | D501: Nivea | E501: 1270120.2 | F501: 1683681.5

Sheet Customers
A1: Customer_ID | B1: Customer_Name | C1: Gender | D1: Age | E1: Customer_Type
A2: C101 | B2: Aman | C2: Male | D2: 24 | E2: New
A3: C102 | B3: Rahul | C3: Male | D3: 28 | E3: Returning
A4: C103 | B4: Priya | C4: Female | D4: 25 | E4: New
A5: C104 | B5: Neha | C5: Female | D5: 31 | E5: Returning
A6: C105 | B6: Rohit | C6: Male | D6: 26 | E6: New
A7: C106 | B7: Anjali | C7: Female | D7: 29 | E7: Returning
A8: C107 | B8: Karan | C8: Male | D8: 35 | E8: New
A9: C108 | B9: Pooja | C9: Female | D9: 27 | E9: Returning
A10: C109 | B10: Vikas | C10: Male | D10: 32 | E10: New
A11: C110 | B11: Simran | C11: Female | D11: 24 | E11: Returning
A12: C111 | B12: Arjun | C12: Male | D12: 30 | E12: New
A13: C112 | B13: Riya | C13: Female | D13: 26 | E13: Returning
... A501: C600 | B501: Rohit | C501: Male | D501: 116.25714 | E501: New

Sheet Employees
A1: Emp_ID | B1: Employee_Name | C1: Department | D1: Target_Sales
A2: E01 | B2: Amit | C2: Sales | D2: 450000
A3: E02 | B3: Rahul | C3: Sales | D3: 500000
A4: E03 | B4: Priya | C4: Sales | D4: 400000
A5: E04 | B5: Neha | C5: Sales | D5: 475000
A6: E05 | B6: Rohit | C6: Sales | D6: 425000
A7: E06 | B7: Amit | C7: Sales | D7: 427500
A8: E07 | B8: Rahul | C8: Sales | D8: 420000
A9: E08 | B9: Priya | C9: Sales | D9: 412500
A10: E09 | B10: Neha | C10: Sales | D10: 405000
A11: E10 | B11: Rohit | C11: Sales | D11: 397500
A12: E11 | B12: Amit | C12: Sales | D12: 390000
A13: E12 | B13: Rahul | C13: Sales | D13: 382500
... A501: E500 | B501: Rohit | C501: Sales | D501: 3277500

Sheet Targets
A1: Month | B1: Target_Sales
A2: April | B2: 2500000
A3: May | B3: 2800000
A4: June | B4: 3000000
A5: July | B5: 3200000
A6: August | B6: 3500000
A7: September | B7: 3800000
A8: October | B8: 4013333.3
A9: November | B9: 4264761.9
A10: December | B10: 4516190.5
A11: January | B11: 4767619
A12: February | B12: 5019047.6
A13: March | B13: 5270476.2
... A501: November | B501: 1.2796762e+08

Sheet Sheet1
A3: Row Labels | B3: Sum of Total Sales
A4: Beauty | B4: 55018.394
A5: Clothing | B5: 586825.11
A6: Electronics | B6: 12493512
A7: Furniture | B7: 2332948.4
A8: Sports | B8: 642112.93
A9: Grand Total | B9: 16110417

Sheet Analysis
A1: Total Sales | B1: Total Profit | C1: Total Orders | D1: Total Quantity | F1: Average Order Value | G1: Category | H1: Total Sales | I1: Total Profit | J1: Total Qty | K1: Product Name | L1: Total Sales | M1: Total Profit | N1: Total Qty
A2: =SUM(Order!S:S) -> 16791802 | B2: =SUM(Order!U:U) -> 3888538.6 | C2: =COUNTA(Order!A:A)-1 -> 500 | D2: =SUM(Order!H:H) -> 1699.7599 | F2: =A2/C2 -> 33583.604 | G2: Electronics | H2: =SUMIF(Order!M:M,G2,Order!S:S) -> 12493512 | I2: =SUMIF(Order!M:M,Analysis!G2,Order!U:U) -> 2308697.3 | J2: =SUMIF(Order!M:M,G2,Order!H:H) -> 521.96086 | K2: Laptop | L2: =SUMIF(Order!L:L,Analysis!K2,Order!T:T) -> 7687278.7 | M2: =SUMIF(Order!L:L,K2,Order!U:U) -> 1257768 | N2: =SUMIF(Order!L:L,K2,Order!H:H) -> 183.03044
G3: Furniture | H3: =SUMIF(Order!M:M,G3,Order!S:S) -> 2332948.4 | I3: =SUMIF(Order!M:M,Analysis!G3,Order!U:U) -> 770711.73 | J3: =SUMIF(Order!M:M,G3,Order!H:H) -> 328.69345 | K3: Smartphone | L3: =SUMIF(Order!L:L,Analysis!K3,Order!T:T) -> 2165938.8 | M3: =SUMIF(Order!L:L,K3,Order!U:U) -> 858722.65 | N3: =SUMIF(Order!L:L,K3,Order!H:H) -> 154.70992
G4: Clothing | H4: =SUMIF(Order!M:M,G4,Order!S:S) -> 586825.11 | I4: =SUMIF(Order!M:M,Analysis!G4,Order!U:U) -> 264060.46 | J4: =SUMIF(Order!M:M,G4,Order!H:H) -> 351.21652 | K4: Headphones | L4: =SUMIF(Order!L:L,Analysis!K4,Order!T:T) -> 331596.91 | M4: =SUMIF(Order!L:L,K4,Order!U:U) -> 192206.65 | N4: =SUMIF(Order!L:L,K4,Order!H:H) -> 184.2205
G5: Sports | H5: =SUMIF(Order!M:M,G5,Order!S:S) -> 642112.93 | I5: =SUMIF(Order!M:M,Analysis!G5,Order!U:U) -> 287730.28 | J5: =SUMIF(Order!M:M,G5,Order!H:H) -> 161.08303 | K5: Office Chair | L5: =SUMIF(Order!L:L,Analysis!K5,Order!T:T) -> 731075.29 | M5: =SUMIF(Order!L:L,K5,Order!U:U) -> 346827.63 | N5: =SUMIF(Order!L:L,K5,Order!H:H) -> 162.46118
G6: Beauty | H6: =SUMIF(Order!M:M,G6,Order!S:S) -> 55018.394 | I6: =SUMIF(Order!M:M,Analysis!G6,Order!U:U) -> 23141.089 | J6: =SUMIF(Order!M:M,G6,Order!H:H) -> 177.09613 | K6: Study Table | L6: =SUMIF(Order!L:L,Analysis!K6,Order!T:T) -> 831161.34 | M6: =SUMIF(Order!L:L,K6,Order!U:U) -> 423884.09 | N6: =SUMIF(Order!L:L,K6,Order!H:H) -> 166.23227
K7: Shirt | L7: =SUMIF(Order!L:L,Analysis!K7,Order!T:T) -> 111253.65 | M7: =SUMIF(Order!L:L,K7,Order!U:U) -> 100262.97 | N7: =SUMIF(Order!L:L,K7,Order!H:H) -> 158.93378
K8: Jeans | L8: =SUMIF(Order!L:L,Analysis!K8,Order!T:T) -> 211511.01 | M8: =SUMIF(Order!L:L,K8,Order!U:U) -> 163797.49 | N8: =SUMIF(Order!L:L,K8,Order!H:H) -> 192.28274
K9: Sports Shoes | L9: =SUMIF(Order!L:L,Analysis!K9,Order!T:T) -> 354382.66 | M9: =SUMIF(Order!L:L,K9,Order!U:U) -> 287730.28 | N9: =SUMIF(Order!L:L,K9,Order!H:H) -> 161.08303
K10: Face Wash | L10: =SUMIF(Order!L:L,Analysis!K10,Order!T:T) -> 31877.304 | M10: =SUMIF(Order!L:L,K10,Order!U:U) -> 23141.089 | N10: =SUMIF(Order!L:L,K10,Order!H:H) -> 177.09613
A19: Emp_ID | B19: Emp_Name | C19: Total Sales | D19: Total Profit | E19: Target | F19: Achievement % | G19: Target status
A20: E01 | B20: =_xlfn.XLOOKUP(A20,Employees!A:A,Employees!B:B) -> Amit | C20: =SUMIF(Order!E:E,A20,Order!S:S) -> 10172861 | D20: =SUMIF(Order!E:E,A20,Order!U:U) -> 1642926.5 | E20: =_xlfn.XLOOKUP(A20,Order!E:E,Targets!B:B) -> 2500000 | F20: =C20/E20 -> 4.0691445 | G20: =IF(E20>=2600000,"Achieved","Not Achieved") -> Not Achieved
A21: E02 | B21: =_xlfn.XLOOKUP(A21,Employees!A:A,Employees!B:B) -> Rahul | C21: =SUMIF(Order!E:E,A21,Order!S:S) -> 2090187 | D21: =SUMIF(Order!E:E,A21,Order!U:U) -> 637704.58 | E21: =_xlfn.XLOOKUP(A21,Order!E:E,Targets!B:B) -> 3000000 | F21: =C21/E21 -> 0.69672901 | G21: =IF(E21>=2600000,"Achieved","Not Achieved") -> Achieved
A22: E03 | B22: =_xlfn.XLOOKUP(A22,Employees!A:A,Employees!B:B) -> Priya | C22: =SUMIF(Order!E:E,A22,Order!S:S) -> 492779.55 | D22: =SUMIF(Order!E:E,A22,Order!U:U) -> 222848.05 | E22: =_xlfn.XLOOKUP(A22,Order!E:E,Targets!B:B) -> 2800000 | F22: =C22/E22 -> 0.1759927 | G22: =IF(E22>=2600000,"Achieved","Not Achieved") -> Achieved
A23: E04 | B23: =_xlfn.XLOOKUP(A23,Employees!A:A,Employees!B:B) -> Neha | C23: =SUMIF(Order!E:E,A23,Order!S:S) -> 1261445.5 | D23: =SUMIF(Order!E:E,A23,Order!U:U) -> 507572.67 | E23: =_xlfn.XLOOKUP(A23,Order!E:E,Targets!B:B) -> 3200000 | F23: =C23/E23 -> 0.39420172 | G23: =IF(E23>=2600000,"Achieved","Not Achieved") -> Achieved
A24: E05 | B24: =_xlfn.XLOOKUP(A24,Employees!A:A,Employees!B:B) -> Rohit | C24: =SUMIF(Order!E:E,A24,Order!S:S) -> 2774528.6 | D24: =SUMIF(Order!E:E,A24,Order!U:U) -> 877486.71 | E24: =_xlfn.XLOOKUP(A24,Order!E:E,Targets!B:B) -> 3800000 | F24: =C24/E24 -> 0.7301391 | G24: =IF(E24>=2600000,"Achieved","Not Achieved") -> Achieved
B31: City | C31: Total Sales | D31: Total Profit | E31: Orders | G31: Customer_ID | H31: Customer Name | I31: Customer Type | J31: Orders | K31: Total Sales | L31: Total Profit | N31: Top 10 Customers by Sales | P31: Customer Type | Q31: Orders | R31: Total Sales
B32: Delhi | C32: =SUMIF(Order!F:F,B32,Order!T:T) -> 5792471.4 | D32: =SUMIF(Order!F:F,B32,Order!U:U) -> 1672716.1 | E32: =COUNTIF(Order!F:F,B32) -> 172 | G32: C101 | H32: =_xlfn.XLOOKUP(Analysis!G35,Customers!A:A,Customers!B:B) -> Rahul | I32: =_xlfn.XLOOKUP(Analysis!G32,Customers!A:A,Customers!E:E) -> New | J32: =COUNTIF(Order!C:C,G32) -> 40 | K32: =SUMIF(Order!C:C,G32,Order!T:T) -> 3875387.8 | L32: =SUMIF(Order!C:C,G32,Order!U:U) -> 754054.37 | N32: =INDEX($H$32:$H$46,MATCH(LARGE($K$32:$K$46,ROWS(H$32:N32)),$K$32:$K$46,0)) -> Rahul | P32: New | Q32: =SUMIF(Analysis!I32:I46,P32,Analysis!J32:J46) -> 274 | R32: =SUMIF(I32:I46,P32,K32:K46) -> 10586130
B33: Noida | C33: =SUMIF(Order!F:F,B33,Order!T:T) -> 3426598.1 | D33: =SUMIF(Order!F:F,B33,Order!U:U) -> 1008247.1 | E33: =COUNTIF(Order!F:F,B33) -> 118 | G33: C111 | H33: =_xlfn.XLOOKUP(Analysis!G36,Customers!A:A,Customers!B:B) -> Rohit | I33: =_xlfn.XLOOKUP(Analysis!G42,Customers!A:A,Customers!E:E) -> New | J33: =COUNTIF(Order!C:C,G33) -> 31 | K33: =SUMIF(Order!C:C,G33,Order!T:T) -> 3270029.2 | L33: =SUMIF(Order!C:C,G33,Order!U:U) -> 559950.96 | N33: =INDEX($H$32:$H$46,MATCH(LARGE($K$32:$K$46,ROWS(H$32:N33)),$K$32:$K$46,0)) -> Rohit | P33: Returning | Q33: =SUMIF(Analysis!I33:I47,P33,Analysis!J33:J47) -> 226 | R33: =SUMIF(I33:I47,P33,K33:K47) -> 2317133.1
B34: Ghaziabad | C34: =SUMIF(Order!F:F,B34,Order!T:T) -> 2503160.1 | D34: =SUMIF(Order!F:F,B34,Order!U:U) -> 576228.22 | E34: =COUNTIF(Order!F:F,B34) -> 70 | G34: C106 | H34: =_xlfn.XLOOKUP(Analysis!G37,Customers!A:A,Customers!B:B) -> Karan | I34: =_xlfn.XLOOKUP(Analysis!G37,Customers!A:A,Customers!E:E) -> New | J34: =COUNTIF(Order!C:C,G34) -> 31 | K34: =SUMIF(Order!C:C,G34,Order!T:T) -> 1830504.5 | L34: =SUMIF(Order!C:C,G34,Order!U:U) -> 487475.25 | N34: =INDEX($H$32:$H$46,MATCH(LARGE($K$32:$K$46,ROWS(H$32:N34)),$K$32:$K$46,0)) -> Karan
B35: Jaipur | C35: =SUMIF(Order!F:F,B35,Order!T:T) -> 8760.2218 | D35: =SUMIF(Order!F:F,B35,Order!U:U) -> 6393.2136 | E35: =COUNTIF(Order!F:F,B35) -> 15 | G35: C102 | H35: =_xlfn.XLOOKUP(Analysis!G33,Customers!A:A,Customers!B:B) -> Arjun | I35: =_xlfn.XLOOKUP(Analysis!G33,Customers!A:A,Customers!E:E) -> New | J35: =COUNTIF(Order!C:C,G35) -> 40 | K35: =SUMIF(Order!C:C,G35,Order!T:T) -> 560040.56 | L35: =SUMIF(Order!C:C,G35,Order!U:U) -> 261302.15 | N35: =INDEX($H$32:$H$46,MATCH(LARGE($K$32:$K$46,ROWS(H$32:N35)),$K$32:$K$46,0)) -> Arjun
B36: Meerut | C36: =SUMIF(Order!F:F,B36,Order!T:T) -> 940008.11 | D36: =SUMIF(Order!F:F,B36,Order!U:U) -> 475333.24 | E36: =COUNTIF(Order!F:F,B36) -> 78 | G36: C105 | H36: =_xlfn.XLOOKUP(Analysis!G36,Customers!A:A,Customers!B:B) -> Rohit | I36: =_xlfn.XLOOKUP(Analysis!G36,Customers!A:A,Customers!E:E) -> New | J36: =COUNTIF(Order!C:C,G36) -> 39 | K36: =SUMIF(Order!C:C,G36,Order!T:T) -> 540318.34 | L36: =SUMIF(Order!C:C,G36,Order!U:U) -> 267305.46 | N36: =INDEX($H$32:$H$46,MATCH(LARGE($K$32:$K$46,ROWS(H$32:N36)),$K$32:$K$46,0)) -> Rohit | W36: Row Labels | X36: Sum of Total Sales
B37: Gurugram | C37: =SUMIF(Order!F:F,B37,Order!T:T) -> 232265.41 | D37: =SUMIF(Order!F:F,B37,Order!U:U) -> 149620.62 | E37: =COUNTIF(Order!F:F,B37) -> 47 | G37: C107 | H37: =_xlfn.XLOOKUP(Analysis!G38,Customers!A:A,Customers!B:B) -> Simran | I37: =_xlfn.XLOOKUP(Analysis!G38,Customers!A:A,Customers!E:E) -> Returning | J37: =COUNTIF(Order!C:C,G37) -> 31 | K37: =SUMIF(Order!C:C,G37,Order!T:T) -> 530708.97 | L37: =SUMIF(Order!C:C,G37,Order!U:U) -> 237775.16 | N37: =INDEX($H$32:$H$46,MATCH(LARGE($K$32:$K$46,ROWS(H$32:N37)),$K$32:$K$46,0)) -> Simran | W37: Delhi | X37: 5792471.4
B38: Meerut | C38: =SUMIF(Order!F:F,B38,Order!T:T) -> 940008.11 | D38: =SUMIF(Order!F:F,B38,Order!U:U) -> 475333.24 | E38: =COUNTIF(Order!F:F,B38) -> 78 | G38: C110 | H38: =_xlfn.XLOOKUP(Analysis!G41,Customers!A:A,Customers!B:B) -> Neha | I38: =_xlfn.XLOOKUP(Analysis!G41,Customers!A:A,Customers!E:E) -> Returning | J38: =COUNTIF(Order!C:C,G38) -> 31 | K38: =SUMIF(Order!C:C,G38,Order!T:T) -> 519221.51 | L38: =SUMIF(Order!C:C,G38,Order!U:U) -> 262998.19 | N38: =INDEX($H$32:$H$46,MATCH(LARGE($K$32:$K$46,ROWS(H$32:N38)),$K$32:$K$46,0)) -> Neha | W38: Ghaziabad | X38: 2503160.1
G39: C112 | H39: =_xlfn.XLOOKUP(Analysis!G43,Customers!A:A,Customers!B:B) -> Shreya | I39: =_xlfn.XLOOKUP(Analysis!G43,Customers!A:A,Customers!E:E) -> Returning | J39: =COUNTIF(Order!C:C,G39) -> 31 | K39: =SUMIF(Order!C:C,G39,Order!T:T) -> 414467.37 | L39: =SUMIF(Order!C:C,G39,Order!U:U) -> 179840.08 | N39: =INDEX($H$32:$H$46,MATCH(LARGE($K$32:$K$46,ROWS(H$32:N39)),$K$32:$K$46,0)) -> Shreya | W39: Gurugram | X39: 232265.41
G40: C115 | H40: =_xlfn.XLOOKUP(Analysis!G46,Customers!A:A,Customers!B:B) -> Pooja | I40: =_xlfn.XLOOKUP(Analysis!G46,Customers!A:A,Customers!E:E) -> Returning | J40: =COUNTIF(Order!C:C,G40) -> 24 | K40: =SUMIF(Order!C:C,G40,Order!T:T) -> 391515.29 | L40: =SUMIF(Order!C:C,G40,Order!U:U) -> 188629.04 | N40: =INDEX($H$32:$H$46,MATCH(LARGE($K$32:$K$46,ROWS(H$32:N40)),$K$32:$K$46,0)) -> Pooja | W40: Jaipur | X40: 8760.2218
G41: C104 | H41: =_xlfn.XLOOKUP(Analysis!G35,Customers!A:A,Customers!B:B) -> Rahul | I41: =_xlfn.XLOOKUP(Analysis!G35,Customers!A:A,Customers!E:E) -> Returning | J41: =COUNTIF(Order!C:C,G41) -> 39 | K41: =SUMIF(Order!C:C,G41,Order!T:T) -> 322926.29 | L41: =SUMIF(Order!C:C,G41,Order!U:U) -> 202901.72 | N41: =INDEX($H$32:$H$46,MATCH(LARGE($K$32:$K$46,ROWS(H$32:N41)),$K$32:$K$46,0)) -> Rahul | W41: Meerut | X41: 1880016.2
G42: C109 | H42: =_xlfn.XLOOKUP(Analysis!G40,Customers!A:A,Customers!B:B) -> Varun | I42: =_xlfn.XLOOKUP(Analysis!G40,Customers!A:A,Customers!E:E) -> New | J42: =COUNTIF(Order!C:C,G42) -> 31 | K42: =SUMIF(Order!C:C,G42,Order!T:T) -> 224868.57 | L42: =SUMIF(Order!C:C,G42,Order!U:U) -> 170461.24 | W42: Noida | X42: 3426598.1
G43: C114 | H43: =_xlfn.XLOOKUP(Analysis!G45,Customers!A:A,Customers!B:B) -> Mohit | I43: =_xlfn.XLOOKUP(Analysis!G45,Customers!A:A,Customers!E:E) -> New | J43: =COUNTIF(Order!C:C,G43) -> 31 | K43: =SUMIF(Order!C:C,G43,Order!T:T) -> 206077.98 | L43: =SUMIF(Order!C:C,G43,Order!U:U) -> 134209.71 | W43: Grand Total | X43: 13843272
G44: C103 | H44: =_xlfn.XLOOKUP(Analysis!G34,Customers!A:A,Customers!B:B) -> Anjali | I44: =_xlfn.XLOOKUP(Analysis!G34,Customers!A:A,Customers!E:E) -> Returning | J44: =COUNTIF(Order!C:C,G44) -> 39 | K44: =SUMIF(Order!C:C,G44,Order!T:T) -> 79245.936 | L44: =SUMIF(Order!C:C,G44,Order!U:U) -> 65682.47
G45: C113 | H45: =_xlfn.XLOOKUP(Analysis!G44,Customers!A:A,Customers!B:B) -> Priya | I45: =_xlfn.XLOOKUP(Analysis!G44,Customers!A:A,Customers!E:E) -> New | J45: =COUNTIF(Order!C:C,G45) -> 31 | K45: =SUMIF(Order!C:C,G45,Order!T:T) -> 78903.402 | L45: =SUMIF(Order!C:C,G45,Order!U:U) -> 63381.666
G46: C108 | H46: =_xlfn.XLOOKUP(Analysis!G39,Customers!A:A,Customers!B:B) -> Riya | I46: =_xlfn.XLOOKUP(Analysis!G39,Customers!A:A,Customers!E:E) -> Returning | J46: =COUNTIF(Order!C:C,G46) -> 31 | K46: =SUMIF(Order!C:C,G46,Order!T:T) -> 59047.704 | L46: =SUMIF(Order!C:C,G46,Order!U:U) -> 52571.109 | AJ46: Row Labels | AK46: Sum of Total Sales
AJ47: New | AK47: 10586130
AJ48: Returning | AK48: 2317133.1
A49: Product Name | B49: Total Sales | C49: Total Profit | D49: Total Qty | AJ49: Grand Total | AK49: 12903263
A50: Laptop | B50: =SUMIF(Order!L:L,Analysis!A50,Order!T:T) -> 7687278.7 | C50: =SUMIF(Order!L:L,Analysis!A50,Order!U:U) -> 1257768 | D50: =SUMIF(Order!L:L,A50,Order!H:H) -> 183.03044
A51: Smartphone | B51: =SUMIF(Order!L:L,Analysis!A51,Order!T:T) -> 2165938.8 | C51: =SUMIF(Order!L:L,Analysis!A51,Order!U:U) -> 858722.65 | D51: =SUMIF(Order!L:L,A51,Order!H:H) -> 154.70992
A52: Headphones | B52: =SUMIF(Order!L:L,Analysis!A52,Order!T:T) -> 331596.91 | C52: =SUMIF(Order!L:L,Analysis!A52,Order!U:U) -> 192206.65 | D52: =SUMIF(Order!L:L,A52,Order!H:H) -> 184.2205
A53: Office Chair | B53: =SUMIF(Order!L:L,Analysis!A53,Order!T:T) -> 731075.29 | C53: =SUMIF(Order!L:L,Analysis!A53,Order!U:U) -> 346827.63 | D53: =SUMIF(Order!L:L,A53,Order!H:H) -> 162.46118
A54: Study Table | B54: =SUMIF(Order!L:L,Analysis!A54,Order!T:T) -> 831161.34 | C54: =SUMIF(Order!L:L,Analysis!A54,Order!U:U) -> 423884.09 | D54: =SUMIF(Order!L:L,A54,Order!H:H) -> 166.23227
...

Sheet Dashboard
